<mujoco model = "MiniArm">
  <compiler angle="radian" meshdir="meshes/"/>
  <!-- <option timestep="0.001" gravity="0 0 -9.81" /> -->
  <!-- <option tolerance="0.0001" integrator="RK4"/> -->
  <option integrator="RK4"/>
  <asset>
    <mesh name="arm_base" file="BaseLink.stl" scale="10 10 10"/>
    <mesh name="column_link" file="ColumnLink.stl" scale="10 10 10"/>
    <mesh name="shoulder_pitch" file="ShoulderPitch.stl" scale="10 10 10"/>
    <mesh name="Arm1" file="ArmLink1.stl" scale="10 10 10"/>
    <mesh name="Arm2" file="ArmLink2.stl" scale="10 10 10"/>
    <mesh name="wrist_pitch" file="WristPitch.stl" scale="10 10 10"/>
    <mesh name="EE_link" file="EE_Frame.stl" scale="10 10 10"/>
    <texture type="skybox" builtin="gradient" rgb1=".3 .5 .7" rgb2="0 0 0" width="32" height="512"/>
    <texture name="body" type="cube" builtin="flat" mark="cross" width="128" height="128" rgb1="0.8 0.6 0.4" rgb2="0.8 0.6 0.4" markrgb="1 1 1" random="0.01"/>
    <material name="body" texture="body" texuniform="true" rgba="0.8 0.6 .4 1"/>
    <texture name="grid" type="2d" builtin="checker" width="512" height="512" rgb1=".1 .2 .3" rgb2=".2 .3 .4"/>
    <material name="grid" texture="grid" texrepeat="1 1" texuniform="true" reflectance=".2"/>
    <material name="red_material" rgba="1 0 0 1"/>  # red
    <material name="orange_material" rgba="1 0.5 0 1"/>  # orange
    <material name="blue_material" rgba="0 0 1 1"/>  # blue
    <material name="green_material" rgba="0 1 0 1"/>  # green
    <material name="yellow_material" rgba="1 1 0 1"/>  # yellow
    <material name="purple_material" rgba="1 0 1 1"/>  # purple
    <material name="pink_material" rgba="1 0.75 0.75 1"/>  # pink
    <material name="white_material" rgba="1 1 1 1"/>  # white
  </asset>
  <visual>
    <global offwidth="700" offheight="400"/>  
  </visual>
  <worldbody>
    <geom name="floor" size="0 0 .05" type="plane" material="grid" condim="3"/>

    <!-- <camera name="my_camera" pos="0 -3 5" euler="0.8 0 0" mode="track"/> -->
    <light name="top" pos="0 0 2.5"/>
    <light name="top2" pos="0 0 2.5"/>

    <body name="base" euler="0 0 0">
      <geom type="mesh" contype="0"  conaffinity="0" density="0" mesh="arm_base" />

      <body name="colum_link" pos="-0.06 0 0">
        <joint name="base_yaw" type="hinge" axis="0 0 1" pos="0 0 0" armature="0.005"/>
        <inertial pos="0.0 0 0.2" quat="1 0 0 0" mass="2.5" diaginertia="0.00176331 0.00174734 0.000400822"/>
        <geom type="mesh" contype="0"  conaffinity="0" density="0" mesh="column_link" material="orange_material"/>

        <body name="shoulder_pitch" pos="0 0 0.4">
          <joint name="shoulder_pitch" type="hinge" axis="0 1 0" pos="0 0 0" armature="0.005"/>
          <inertial pos="0.0 0 0.0" quat="1 0 0 0" mass="2.3" diaginertia="0.00176331 0.00174734 0.000400822"/>
          <geom type="mesh" contype="0"  conaffinity="0" density="0" mesh="shoulder_pitch" material="blue_material"/>

          <body name="UpperArm" pos="0 0 0">
            <joint name="shoulder_roll" type="hinge" axis="1 0 0" pos="0 0 0" armature="0.005"/>
            <inertial pos="0.3 0 0.0" quat="1 0 0 0" mass="1.8" diaginertia="0.00176331 0.00174734 0.000400822"/>
            <geom type="mesh" contype="0"  conaffinity="0" density="0" mesh="Arm1" material="green_material"/>

            <body name="LowerArm" pos="0.55 0 0">
              <joint name="elbow" type="hinge" axis="0 1 0" pos="0 0 0" armature="0.005"/>
              <inertial pos="0.25 0 0.0" quat="1 0 0 0" mass="1.3" diaginertia="0.00176331 0.00174734 0.000400822"/>
              <geom type="mesh" contype="0"  conaffinity="0" density="0" mesh="Arm2" material="yellow_material"/>

              <body name="WristPitch" pos="0.45 0 0">
                <joint name="wrist_pitch" type="hinge" axis="0 1 0" pos="0 0 0" armature="0.01"/>
                <inertial pos="0.0 0 0" quat="1 0 0 0" mass="0.5" diaginertia="0.001 0.0004 0.001"/>
                <geom type="mesh" contype="0"  conaffinity="0" density="0" mesh="wrist_pitch" material="purple_material"/>

                <body name="EE_box" pos="0.15 0 0">
                  <joint name="wrist_roll" type="hinge" axis="1 0 0" pos="0 0 0" armature="0.005"/>
                  <inertial pos="0.07 0 0" quat="1 0 0 0" mass="0.2" diaginertia="0.001 0.003 0.003"/>
                  <geom name="box_outer" type="box" size="0.1 0.035 0.035" condim="3" contype="1" conaffinity="1" solimp="0.99 0.99 0.0001 0.1 4"/>
                  <!-- <geom name="capsule_EE" type="capsule" size="0.1 0.035 0.035" condim="3" contype="1" conaffinity="1" /> -->
                  <!-- <geom name="EE_box" type="box" type="box" size="0.1 0.1 0.1"/> -->
                  <site name="ee_site" pos="0.1 0 0" size="0.005" rgba="0 0 1 1"/>

                </body>
              </body>
            </body>
          </body>
        </body>
      </body>
    </body>
    <body name="box_mould" pos="0 0 -0.6" euler="0 -1.0 0">
      <inertial pos="0.0 0 0" quat="1 0 0 0" mass="5.0" diaginertia="0.001 0.003 0.003"/>
      <joint name="box_mould_slide_x" type="slide" axis="1 0 0"/>
      <joint name="box_mould_slide_y" type="slide" axis="0 1 0"/>
      <geom type="box" size="0.08 0.2 0.04" pos="-0.12 0 0" rgba="1 0 0 1" condim="3" contype="1" conaffinity="1" solimp="0.99 0.99 0.0001 0.1 4"/>
      <geom type="box" size="0.08 0.2 0.04" pos="0.12 0 0" rgba="1 0 0 1" condim="3" contype="1" conaffinity="1" solimp="0.99 0.99 0.0001 0.1 4"/>
      <geom type="box" size="0.2 0.08 0.04" pos="0 0.12 0" rgba="1 0 0 1" condim="3" contype="1" conaffinity="1" solimp="0.99 0.99 0.0001 0.1 4"/>
      <geom type="box" size="0.2 0.08 0.04" pos="0 -0.12 0" rgba="1 0 0 1" condim="3" contype="1" conaffinity="1" solimp="0.99 0.99 0.0001 0.1 4"/>

    <!-- Base plate -->
      <!-- <geom type="box" size="0.2 0.2 0.0075" pos="0 0 -0.0325" rgba="1 0 0 1" contype="1" conaffinity="1"/> -->
    <!-- detection plate -->
    <!-- <geom type="box" size="0.035 0.035 0.0075" pos="0 0 -0.04" rgba="1 0 0 1" condim="3" contype="1" conaffinity="1"/> -->

    <!-- Sites positioned at the 4 corners of the 7cm x 7cm hole -->
      <site name="mould_pos1_site" pos="-0.035 0.035 0.04" size="0.01" rgba="0 0 1 1"/>
      <site name="mould_pos2_site" pos="-0.035 -0.035 0.04" size="0.01" rgba="0 0 1 1"/>
      <site name="mould_pos3_site" pos="0.035 -0.035 0.04" size="0.01" rgba="0 0 1 1"/>
      <site name="mould_pos4_site" pos="0.035 0.035 0.04" size="0.01" rgba="0 0 1 1"/>
    <body name = "detection_plate" pos="0 0 0" euler="0 0 0">
      <geom type="box" size="0.035 0.035 0.0075" pos="0 0 -0.04" rgba="1 0 0 1" condim="3" contype="1" conaffinity="1"/>
    </body>
    </body>
  </worldbody>
<!-- Add actuators for the joints -->
  <actuator>
    <motor joint="base_yaw" ctrllimited="true" ctrlrange="-20 20" gear="1"/>
    <motor joint="shoulder_pitch" ctrllimited="true" ctrlrange="-25 25" gear="1"/>
    <motor joint="shoulder_roll" ctrllimited="true" ctrlrange="-15 15" gear="1"/>
    <motor joint="elbow" ctrllimited="true" ctrlrange="-20 20" gear="1"/>
    <motor joint="wrist_pitch" ctrllimited="true" ctrlrange="-20 20" gear="1"/>
    <motor joint="wrist_roll" ctrllimited="true" ctrlrange="-10 10" gear="1"/>
    <motor joint="box_mould_slide_x" ctrllimited="true" ctrlrange="-50 50" gear="1"/>
    <motor joint="box_mould_slide_y" ctrllimited="true" ctrlrange="-50 50" gear="1"/>
  </actuator>

  <sensor>
    <framepos name="mould_pos_sensor1" objtype="site" objname="mould_pos1_site"/>
    <framepos name="mould_pos_sensor2" objtype="site" objname="mould_pos2_site"/>
    <framepos name="mould_pos_sensor3" objtype="site" objname="mould_pos3_site"/>
    <framepos name="mould_pos_sensor4" objtype="site" objname="mould_pos4_site"/>
  </sensor>

  <keyframe>
    <!-- <key name="init_pose" qpos="1.125 0 0.92 
                                0.987 0 0.16"
                                qvel="0 0 0 
                                0 0 0" />
 -->
    <key name="init_pose" qpos="0 -1.25 0 
                                1.5 0.86 0 
                                1.5 0.0"
                                qvel="0 0 0 
                                0 0 0 
                                0 0" />

                                
    <!-- <key name="init_pose" qpos="0 -0.0025 0 
                                -1.5 0.86"
                                qvel="0 0 0 
                                0 0" /> -->
    <!-- <key name="init_pose" qpos="0 -0.144 0 
                                -1.6 1.74 0"
                                qvel="0 0 0 
                                0 0 0" /> -->
    </keyframe>
</mujoco>